{
    "registryname": "transformer",
    "localizedname": "Power Transformer",
    "parts": [
        {
            "x": 1,
            "y": -1,
            "z": 0,
            "elements": "minecraft:stone_bricks"
        },
        {
            "x": 0,
            "y": -1,
            "z": 0,
            "elements": "minecraft:stone_bricks"
        },
        {
            "x": -1,
            "y": -1,
            "z": 0,
            "elements": "minecraft:stone_bricks"
        },

        {
            "x": 1,
            "y": -1,
            "z": 1,
            "elements": "minecraft:stone_bricks"
        },
        {
            "x": 0,
            "y": -1,
            "z": 1,
            "elements": "minecraft:stone_bricks"
        },
        {
            "x": -1,
            "y": -1,
            "z": 1,
            "elements": "minecraft:stone_bricks"
        },

        {
            "x": 1,
            "y": -1,
            "z": 2,
            "elements": "minecraft:stone_bricks"
        },
        {
            "x": 0,
            "y": -1,
            "z": 2,
            "elements": "minecraft:stone_bricks"
        },
        {
            "x": -1,
            "y": -1,
            "z": 2,
            "elements": "minecraft:stone_bricks"
        },

        {
            "x": -1,
            "y": 0,
            "z": 1,
            "elements": "modularmachinery:blockenergyoutputhatch"
        },
        {
            "x": 1,
            "y": 0,
            "z": 1,
            "elements": "modularmachinery:blockenergyinputhatch"
        },
        {
            "x": 0,
            "y": 0,
            "z": 2,
            "elements": "casings_decorative"
        },
        {
            "x": -1,
            "y": 0,
            "z": 0,
            "elements": "minecraft:iron_bars"
        },
        {
            "x": 1,
            "y": 0,
            "z": 0,
            "elements": "minecraft:iron_bars"
        },
        {
            "x": -1,
            "y": 0,
            "z": 2,
            "elements": "minecraft:iron_bars"
        },
        {
            "x": 1,
            "y": 0,
            "z": 2,
            "elements": "minecraft:iron_bars"
        },

        {
            "x": 0,
            "y": 0,
            "z": 1,
            "elements": "minecraft:redstone_block"
        },
        {
            "x": 0,
            "y": 1,
            "z": 1,
            "elements": "minecraft:redstone_block"
        },
        {
            "x": 0,
            "y": 2,
            "z": 1,
            "elements": "minecraft:redstone_block"
        },
        {
            "x": 0,
            "y": 3,
            "z": 1,
            "elements": "minecraft:iron_block"
        },

        {
            "x": 0,
            "y": 1,
            "z": 0,
            "elements": "minecraft:iron_bars"
        },
        {
            "x": 0,
            "y": 2,
            "z": 0,
            "elements": "minecraft:iron_bars"
        },
        {
            "x": 0,
            "y": 3,
            "z": 0,
            "elements": "minecraft:iron_bars"
        },

        {
            "x": 1,
            "y": 1,
            "z": 1,
            "elements": "minecraft:iron_bars"
        },
        {
            "x": 1,
            "y": 2,
            "z": 1,
            "elements": "minecraft:iron_bars"
        },
        {
            "x": 1,
            "y": 3,
            "z": 1,
            "elements": "minecraft:iron_bars"
        },
        {
            "x": -1,
            "y": 1,
            "z": 1,
            "elements": "minecraft:iron_bars"
        },
        {
            "x": -1,
            "y": 2,
            "z": 1,
            "elements": "minecraft:iron_bars"
        },
        {
            "x": -1,
            "y": 3,
            "z": 1,
            "elements": "minecraft:iron_bars"
        },
        {
            "x": 0,
            "y": 1,
            "z": 2,
            "elements": "minecraft:iron_bars"
        },
        {
            "x": 0,
            "y": 2,
            "z": 2,
            "elements": "minecraft:iron_bars"
        },
        {
            "x": 0,
            "y": 3,
            "z": 2,
            "elements": "minecraft:iron_bars"
        }
    ]
}
